Workbook
Name Archivo_Edita_Nombre: Configura!$B$23
Name Archivo_Nombre: IFERROR(Nombre_Archivo,Archivo_Edita_Nombre)
Name DatosKanban: Datos!$A$2:$K$101
Name Fecha_Hoy: TODAY()
Name ListaCriticidad: Configura!$D$9:$D$11
Name ListaEstados: Configura!$B$9:$B$18
Name ListaUsuarios: Configura!$F$9:$F$23
Name miAsignado: KANBAN!$J$2
Name miCabeceraFinal: Datos!$G$1
Name miCabeceraInicio: Datos!$E$1
Name miCabeceraPrevisto: Datos!$F$1
Name miCabeceraRetraso: Datos!$I$1
Name miCabeceraTarea: Datos!$C$1
Name miCriticidad: IFERROR(MATCH(KANBAN!$O$2,Configura!$D$9:$D$11,0),"")
Name miDuración: KANBAN!$AI$2
Name miEstadoFinal: Configura!$B$20
Name miFechaInicio: KANBAN!$T$2
Name miIdioma: Configura!$B$5
Name miNúmEstadoFinal: IF(miEstadoFinal="",COUNTA(ListaEstados),MATCH(miEstadoFinal,ListaEstados,0))
Name miNúmLíneas: KANBAN!$F$2
Name miOrdenTarjeta: Configura!$I$9:$I$16
Name miRetraso: KANBAN!$AD$2
Name misAsignados: Datos!$J$2:$J$101
Name misCriticidades: Tareas!$C$2:$C$101
Name misDatosTareas: Datos!$C$1:$J$1
Name misEstados: Tareas!$B$2:$B$101
Name misFechasInicio: Datos!$E$2:$E$101
Name misFiltros: Tareas!$D$2:$D$101
Name misIdiomas: Idiomas!$B$1:INDEX(TablaIdiomas[#Headers],1,COUNTA(TablaIdiomas[#Headers]))
Name misLíneas: COUNTIF(Datos!$1:$1,"?*")+IF(ISNUMBER(miNúmLíneas),miNúmLíneas,1)-9
Name miTexto: KANBAN!$Y$2
Name Nombre_Archivo: MID(Nombre_Ruta,FIND("[",Nombre_Ruta)+1,FIND("]",Nombre_Ruta)-FIND("[",Nombre_Ruta)-1)
Name Nombre_Hoja: MID(Nombre_Ruta,FIND("]",Nombre_Ruta,1)+1,100)
Name Nombre_Ruta: CELL("nombrearchivo",!$A$1)

Sheet KANBAN
B2: =Configura!$B$2 -> Tablero KANBAN v3 ©️ | E2: =Idiomas!$A$22&" " -> Tarjetas con | F2: 8 | G2: =" "&Idiomas!$A$23 -> líneas | I2: =SUM(misFiltros)&" "&Idiomas!$A$24&" " -> 30 tareas asignadas a | N2: =Idiomas!$A$25&" " -> Con criticidad | S2: =Idiomas!$A$26&" " -> Con inicio desde | T2: 44562 | X2: =Idiomas!$A$27&" " -> Con el texto | AC2: =Idiomas!$A$28&" " -> Con un retraso > | AE2: =" "&Idiomas!$A$29 -> días | AH2: =Idiomas!$A$33&" " -> Con una duración > | AJ2: =" "&Idiomas!$A$29 -> días
B4: 1 | C4: {=IFERROR(INDEX(Configura!$B$9:$B$18,B4)&" ("&SUMIF(misEstados,B4,misFiltros)&" de "&SUM(misFiltros)&")","")} -> POR HACER (3 de 30) | F4: ^ | G4: =B4+1 -> 2 | H4: {=IFERROR(INDEX(Configura!$B$9:$B$18,G4)&" ("&SUMIF(misEstados,G4,misFiltros)&" de "&SUM(misFiltros)&")","")} -> EN PROGRESO (2 de 30) | K4: ^ | L4: =G4+1 -> 3 | M4: {=IFERROR(INDEX(Configura!$B$9:$B$18,L4)&" ("&SUMIF(misEstados,L4,misFiltros)&" de "&SUM(misFiltros)&")","")} -> EN ESPERA (1 de 30) | P4: ^ | Q4: =L4+1 -> 4 | R4: {=IFERROR(INDEX(Configura!$B$9:$B$18,Q4)&" ("&SUMIF(misEstados,Q4,misFiltros)&" de "&SUM(misFiltros)&")","")} -> COMPLETADO (24 de 30) | U4: ^ | V4: =Q4+1 -> 5 | W4: {=IFERROR(INDEX(Configura!$B$9:$B$18,V4)&" ("&SUMIF(misEstados,V4,misFiltros)&" de "&SUM(misFiltros)&")","")} -> ARCHIVADO (0 de 30) | Z4: ^ | AA4: =V4+1 -> 6 | AB4: {=IFERROR(INDEX(Configura!$B$9:$B$18,AA4)&" ("&SUMIF(misEstados,AA4,misFiltros)&" de "&SUM(misFiltros)&")","")} -> POR HACER (0 de 30) | AE4: ^ | AF4: =AA4+1 -> 7 | AG4: {=IFERROR(INDEX(Configura!$B$9:$B$18,AF4)&" ("&SUMIF(misEstados,AF4,misFiltros)&" de "&SUM(misFiltros)&")","")} -> EN PROGRESO (0 de 30) | AJ4: ^ | AK4: =AF4+1 -> 8 | AL4: {=IFERROR(INDEX(Configura!$B$9:$B$18,AK4)&" ("&SUMIF(misEstados,AK4,misFiltros)&" de "&SUM(misFiltros)&")","")} -> (0 de 30) | AO4: ^ | AP4: =AK4+1 -> 9 | AQ4: {=IFERROR(INDEX(Configura!$B$9:$B$18,AP4)&" ("&SUMIF(misEstados,AP4,misFiltros)&" de "&SUM(misFiltros)&")","")} -> (0 de 30) | AT4: ^ | AU4: =AP4+1 -> 10 | AV4: {=IFERROR(INDEX(Configura!$B$9:$B$18,AU4)&" ("&SUMIF(misEstados,AU4,misFiltros)&" de "&SUM(misFiltros)&")","")} -> (0 de 30) | AY4: ^
C6: {=IF(OR(Formulas!E3=0,Formulas!E3="",RIGHT(Formulas!F3)="0"),"", HYPERLINK("["&Archivo_Nombre&"]Datos!"&LEFT(SUBSTITUTE(ADDRESS(1,IF(Formulas!E3=1,1,RIGHT(Formulas!F3)+2)),"$",""))&Formulas!D3+1, IFERROR(INDEX(Datos!$A$1:$K$1,1,RIGHT(Formulas!F3)+2)&IF(Formulas!E3=1," "&Formulas!D3,"")&":","")))} -> Tarea 29: | D6: {=IF(OR(Formulas!E3=0,Formulas!E3="",RIGHT(Formulas!F3)="0"),"", HYPERLINK("["&Archivo_Nombre&"]Datos!"&LEFT(SUBSTITUTE(ADDRESS(1,RIGHT(Formulas!F3)+2),"$",""))&Formulas!D3+1, IFERROR(INDEX(Datos!$A$2:$K$101,Formulas!D3,RIGHT(Formulas!F3)+2),"")))} -> Elaboracion Requerimiento N7 | E6: {=IF(OR(Formulas!F4=0,Formulas!F4=""),"",HYPERLINK("["&Archivo_Nombre&"]Datos!"&LEFT(SUBSTITUTE(ADDRESS(1,Formulas!F4+2),"$",""))&Formulas!E4+1, IFERROR(INDEX(Datos!$A$2:$K$101,Formulas!E4,Formulas!F4+2),"")))} -> #VALUE! | H6: {=IF(OR(Formulas!J3=0,Formulas!J3="",RIGHT(Formulas!K3)="0"),"", HYPERLINK("["&Archivo_Nombre&"]Datos!"&LEFT(SUBSTITUTE(ADDRESS(1,IF(Formulas!J3=1,1,RIGHT(Formulas!K3)+2)),"$",""))&Formulas!I3+1, IFERROR(INDEX(Datos!$A$1:$K$1,1,RIGHT(Formulas!K3)+2)&IF(Formulas!J3=1," "&Formulas!I3,"")&":","")))} -> Tarea 26: | I6: {=IF(OR(Formulas!J3=0,Formulas!J3="",RIGHT(Formulas!K3)="0"),"", HYPERLINK("["&Archivo_Nombre&"]Datos!"&LEFT(SUBSTITUTE(ADDRESS(1,RIGHT(Formulas!K3)+2),"$",""))&Formulas!I3+1, IFERROR(INDEX(Datos!$A$2:$K$101,Formulas!I3,RIGHT(Formulas!K3)+2),"")))} -> Sprint 2 | J6: {=IF(OR(Formulas!K4=0,Formulas!K4=""),"",HYPERLINK("["&Archivo_Nombre&"]Datos!"&LEFT(SUBSTITUTE(ADDRESS(1,Formulas!K4+2),"$",""))&Formulas!J4+1, IFERROR(INDEX(Datos!$A$2:$K$101,Formulas!J4,Formulas!K4+2),"")))} -> #VALUE! | M6: {=IF(OR(Formulas!O3=0,Formulas!O3="",RIGHT(Formulas!P3)="0"),"", HYPERLINK("["&Archivo_Nombre&"]Datos!"&LEFT(SUBSTITUTE(ADDRESS(1,IF(Formulas!O3=1,1,RIGHT(Formulas!P3)+2)),"$",""))&Formulas!N3+1, IFERROR(INDEX(Datos!$A$1:$K$1,1,RIGHT(Formulas!P3)+2)&IF(Formulas!O3=1," "&Formulas!N3,"")&":","")))} -> Tarea 30: | N6: {=IF(OR(Formulas!O3=0,Formulas!O3="",RIGHT(Formulas!P3)="0"),"", HYPERLINK("["&Archivo_Nombre&"]Datos!"&LEFT(SUBSTITUTE(ADDRESS(1,RIGHT(Formulas!P3)+2),"$",""))&Formulas!N3+1, IFERROR(INDEX(Datos!$A$2:$K$101,Formulas!N3,RIGHT(Formulas!P3)+2),"")))} -> Tercera Reunion | O6: {=IF(OR(Formulas!P4=0,Formulas!P4=""),"",HYPERLINK("["&Archivo_Nombre&"]Datos!"&LEFT(SUBSTITUTE(ADDRESS(1,Formulas!P4+2),"$",""))&Formulas!O4+1, IFERROR(INDEX(Datos!$A$2:$K$101,Formulas!O4,Formulas!P4+2),"")))} -> #VALUE! | R6: {=IF(OR(Formulas!T3=0,Formulas!T3="",RIGHT(Formulas!U3)="0"),"", HYPERLINK("["&Archivo_Nombre&"]Datos!"&LEFT(SUBSTITUTE(ADDRESS(1,IF(Formulas!T3=1,1,RIGHT(Formulas!U3)+2)),"$",""))&Formulas!S3+1, IFERROR(INDEX(Datos!$A$1:$K$1,1,RIGHT(Formulas!U3)+2)&IF(Formulas!T3=1," "&Formulas!S3,"")&":","")))} -> Tarea 24: | S6: {=IF(OR(Formulas!T3=0,Formulas!T3="",RIGHT(Formulas!U3)="0"),"", HYPERLINK("["&Archivo_Nombre&"]Datos!"&LEFT(SUBSTITUTE(ADDRESS(1,RIGHT(Formulas!U3)+2),"$",""))&Formulas!S3+1, IFERROR(INDEX(Datos!$A$2:$K$101,Formulas!S3,RIGHT(Formulas!U3)+2),"")))} -> Presentacion del primer Sprint | T6: {=IF(OR(Formulas!U4=0,Formulas!U4=""),"",HYPERLINK("["&Archivo_Nombre&"]Datos!"&LEFT(SUBSTITUTE(ADDRESS(1,Formulas!U4+2),"$",""))&Formulas!T4+1, IFERROR(INDEX(Datos!$A$2:$K$101,Formulas!T4,Formulas!U4+2),"")))} -> #VALUE! | W6: {=IF(OR(Formulas!Y3=0,Formulas!Y3="",RIGHT(Formulas!Z3)="0"),"", HYPERLINK("["&Archivo_Nombre&"]Datos!"&LEFT(SUBSTITUTE(ADDRESS(1,IF(Formulas!Y3=1,1,RIGHT(Formulas!Z3)+2)),"$",""))&Formulas!X3+1, IFERROR(INDEX(Datos!$A$1:$K$1,1,RIGHT(Formulas!Z3)+2)&IF(Formulas!Y3=1," "&Formulas!X3,"")&":","")))} | X6: {=IF(OR(Formulas!Y3=0,Formulas!Y3="",RIGHT(Formulas!Z3)="0"),"", HYPERLINK("["&Archivo_Nombre&"]Datos!"&LEFT(SUBSTITUTE(ADDRESS(1,RIGHT(Formulas!Z3)+2),"$",""))&Formulas!X3+1, IFERROR(INDEX(Datos!$A$2:$K$101,Formulas!X3,RIGHT(Formulas!Z3)+2),"")))} | Y6: {=IF(OR(Formulas!Z4=0,Formulas!Z4=""),"",HYPERLINK("["&Archivo_Nombre&"]Datos!"&LEFT(SUBSTITUTE(ADDRESS(1,Formulas!Z4+2),"$",""))&Formulas!Y4+1, IFERROR(INDEX(Datos!$A$2:$K$101,Formulas!Y4,Formulas!Z4+2),"")))} | AB6: {=IF(OR(Formulas!AD3=0,Formulas!AD3="",RIGHT(Formulas!AE3)="0"),"", HYPERLINK("["&Archivo_Nombre&"]Datos!"&LEFT(SUBSTITUTE(ADDRESS(1,IF(Formulas!AD3=1,1,RIGHT(Formulas!AE3)+2)),"$",""))&Formulas!AC3+1, IFERROR(INDEX(Datos!$A$1:$K$1,1,RIGHT(Formulas!AE3)+2)&IF(Formulas!AD3=1," "&Formulas!AC3,"")&":","")))} | AC6: {=IF(OR(Formulas!AD3=0,Formulas!AD3="",RIGHT(Formulas!AE3)="0"),"", HYPERLINK("["&Archivo_Nombre&"]Datos!"&LEFT(SUBSTITUTE(ADDRESS(1,RIGHT(Formulas!AE3)+2),"$",""))&Formulas!AC3+1, IFERROR(INDEX(Datos!$A$2:$K$101,Formulas!AC3,RIGHT(Formulas!AE3)+2),"")))} | AD6: {=IF(OR(Formulas!AE4=0,Formulas!AE4=""),"",HYPERLINK("["&Archivo_Nombre&"]Datos!"&LEFT(SUBSTITUTE(ADDRESS(1,Formulas!AE4+2),"$",""))&Formulas!AD4+1, IFERROR(INDEX(Datos!$A$2:$K$101,Formulas!AD4,Formulas!AE4+2),"")))} | AG6: {=IF(OR(Formulas!AI3=0,Formulas!AI3="",RIGHT(Formulas!AJ3)="0"),"", HYPERLINK("["&Archivo_Nombre&"]Datos!"&LEFT(SUBSTITUTE(ADDRESS(1,IF(Formulas!AI3=1,1,RIGHT(Formulas!AJ3)+2)),"$",""))&Formulas!AH3+1, IFERROR(INDEX(Datos!$A$1:$K$1,1,RIGHT(Formulas!AJ3)+2)&IF(Formulas!AI3=1," "&Formulas!AH3,"")&":","")))} | AH6: {=IF(OR(Formulas!AI3=0,Formulas!AI3="",RIGHT(Formulas!AJ3)="0"),"", HYPERLINK("["&Archivo_Nombre&"]Datos!"&LEFT(SUBSTITUTE(ADDRESS(1,RIGHT(Formulas!AJ3)+2),"$",""))&Formulas!AH3+1, IFERROR(INDEX(Datos!$A$2:$K$101,Formulas!AH3,RIGHT(Formulas!AJ3)+2),"")))} | AI6: {=IF(OR(Formulas!AJ4=0,Formulas!AJ4=""),"",HYPERLINK("["&Archivo_Nombre&"]Datos!"&LEFT(SUBSTITUTE(ADDRESS(1,Formulas!AJ4+2),"$",""))&Formulas!AI4+1, IFERROR(INDEX(Datos!$A$2:$K$101,Formulas!AI4,Formulas!AJ4+2),"")))} | AL6: {=IF(OR(Formulas!AN3=0,Formulas!AN3="",RIGHT(Formulas!AO3)="0"),"", HYPERLINK("["&Archivo_Nombre&"]Datos!"&LEFT(SUBSTITUTE(ADDRESS(1,IF(Formulas!AN3=1,1,RIGHT(Formulas!AO3)+2)),"$",""))&Formulas!AM3+1, IFERROR(INDEX(Datos!$A$1:$K$1,1,RIGHT(Formulas!AO3)+2)&IF(Formulas!AN3=1," "&Formulas!AM3,"")&":","")))} | AM6: {=IF(OR(Formulas!AN3=0,Formulas!AN3="",RIGHT(Formulas!AO3)="0"),"", HYPERLINK("["&Archivo_Nombre&"]Datos!"&LEFT(SUBSTITUTE(ADDRESS(1,RIGHT(Formulas!AO3)+2),"$",""))&Formulas!AM3+1, IFERROR(INDEX(Datos!$A$2:$K$101,Formulas!AM3,RIGHT(Formulas!AO3)+2),"")))} | AN6: {=IF(OR(Formulas!AO4=0,Formulas!AO4=""),"",HYPERLINK("["&Archivo_Nombre&"]Datos!"&LEFT(SUBSTITUTE(ADDRESS(1,Formulas!AO4+2),"$",""))&Formulas!AN4+1, IFERROR(INDEX(Datos!$A$2:$K$101,Formulas!AN4,Formulas!AO4+2),"")))} | AQ6: {=IF(OR(Formulas!AS3=0,Formulas!AS3="",RIGHT(Formulas!AT3)="0"),"", HYPERLINK("["&Archivo_Nombre&"]Datos!"&LEFT(SUBSTITUTE(ADDRESS(1,IF(Formulas!AS3=1,1,RIGHT(Formulas!AT3)+2)),"$",""))&Formulas!AR3+1, IFERROR(INDEX(Datos!$A$1:$K$1,1,RIGHT(Formulas!AT3)+2)&IF(Formulas!AS3=1," "&Formulas!AR3,"")&":","")))} | AR6: {=IF(OR(Formulas!AS3=0,Formulas!AS3="",RIGHT(Formulas!AT3)="0"),"", HYPERLINK("["&Archivo_Nombre&"]Datos!"&LEFT(SUBSTITUTE(ADDRESS(1,RIGHT(Formulas!AT3)+2),"$",""))&Formulas!AR3+1, IFERROR(INDEX(Datos!$A$2:$K$101,Formulas!AR3,RIGHT(Formulas!AT3)+2),"")))} | AS6: {=IF(OR(Formulas!AT4=0,Formulas!AT4=""),"",HYPERLINK("["&Archivo_Nombre&"]Datos!"&LEFT(SUBSTITUTE(ADDRESS(1,Formulas!AT4+2),"$",""))&Formulas!AS4+1, IFERROR(INDEX(Datos!$A$2:$K$101,Formulas!AS4,Formulas!AT4+2),"")))} | AV6: {=IF(OR(Formulas!AX3=0,Formulas!AX3="",RIGHT(Formulas!AY3)="0"),"", HYPERLINK("["&Archivo_Nombre&"]Datos!"&LEFT(SUBSTITUTE(ADDRESS(1,IF(Formulas!AX3=1,1,RIGHT(Formulas!AY3)+2)),"$",""))&Formulas!AW3+1, IFERROR(INDEX(Datos!$A$1:$K$1,1,RIGHT(Formulas!AY3)+2)&IF(Formulas!AX3=1," "&Formulas!AW3,"")&":","")))} | AW6: {=IF(OR(Formulas!AX3=0,Formulas!AX3="",RIGHT(Formulas!AY3)="0"),"", HYPERLINK("["&Archivo_Nombre&"]Datos!"&LEFT(SUBSTITUTE(ADDRESS(1,RIGHT(Formulas!AY3)+2),"$",""))&Formulas!AW3+1, IFERROR(INDEX(Datos!$A$2:$K$101,Formulas!AW3,RIGHT(Formulas!AY3)+2),"")))} | AX6: {=IF(OR(Formulas!AY4=0,Formulas!AY4=""),"",HYPERLINK("["&Archivo_Nombre&"]Datos!"&LEFT(SUBSTITUTE(ADDRESS(1,Formulas!AY4+2),"$",""))&Formulas!AX4+1, IFERROR(INDEX(Datos!$A$2:$K$101,Formulas!AX4,Formulas!AY4+2),"")))}
C7: {=IF(OR(Formulas!E4=0,Formulas!E4="",RIGHT(Formulas!F4)="0"),"", HYPERLINK("["&Archivo_Nombre&"]Datos!"&LEFT(SUBSTITUTE(ADDRESS(1,IF(Formulas!E4=1,1,RIGHT(Formulas!F4)+2)),"$",""))&Formulas!D4+1, IFERROR(INDEX(Datos!$A$1:$K$1,1,RIGHT(Formulas!F4)+2)&IF(Formulas!E4=1," "&Formulas!D4,"")&":","")))} -> Descripción: | D7: {=IF(OR(Formulas!E4=0,Formulas!E4="",RIGHT(Formulas!F4)="0"),"", HYPERLINK("["&Archivo_Nombre&"]Datos!"&LEFT(SUBSTITUTE(ADDRESS(1,RIGHT(Formulas!F4)+2),"$",""))&Formulas!D4+1, IFERROR(INDEX(Datos!$A$2:$K$101,Formulas!D4,RIGHT(Formulas!F4)+2),"")))} -> Implementar la funcionalidad del séptimo requerimiento | E7: {=IF(OR(Formulas!F5=0,Formulas!F5=""),"",HYPERLINK("["&Archivo_Nombre&"]Datos!"&LEFT(SUBSTITUTE(ADDRESS(1,Formulas!F5+2),"$",""))&Formulas!E5+1, IFERROR(INDEX(Datos!$A$2:$K$101,Formulas!E5,Formulas!F5+2),"")))} -> #VALUE! | H7: {=IF(OR(Formulas!J4=0,Formulas!J4="",RIGHT(Formulas!K4)="0"),"", HYPERLINK("["&Archivo_Nombre&"]Datos!"&LEFT(SUBSTITUTE(ADDRESS(1,IF(Formulas!J4=1,1,RIGHT(Formulas!K4)+2)),"$",""))&Formulas!I4+1, IFERROR(INDEX(Datos!$A$1:$K$1,1,RIGHT(Formulas!K4)+2)&IF(Formulas!J4=1," "&Formulas!I4,"")&":","")))} -> Descripción: | I7: {=IF(OR(Formulas!J4=0,Formulas!J4="",RIGHT(Formulas!K4)="0"),"", HYPERLINK("["&Archivo_Nombre&"]Datos!"&LEFT(SUBSTITUTE(ADDRESS(1,RIGHT(Formulas!K4)+2),"$",""))&Formulas!I4+1, IFERROR(INDEX(Datos!$A$2:$K$101,Formulas!I4,RIGHT(Formulas!K4)+2),"")))} -> Hito o contenedor de actividades del segundo sprint. | J7: {=IF(OR(Formulas!K5=0,Formulas!K5=""),"",HYPERLINK("["&Archivo_Nombre&"]Datos!"&LEFT(SUBSTITUTE(ADDRESS(1,Formulas!K5+2),"$",""))&Formulas!J5+1, IFERROR(INDEX(Datos!$A$2:$K$101,Formulas!J5,Formulas!K5+2),"")))} -> #VALUE! | M7: {=IF(OR(Formulas!O4=0,Formulas!O4="",RIGHT(Formulas!P4)="0"),"", HYPERLINK("["&Archivo_Nombre&"]Datos!"&LEFT(SUBSTITUTE(ADDRESS(1,IF(Formulas!O4=1,1,RIGHT(Formulas!P4)+2)),"$",""))&Formulas!N4+1, IFERROR(INDEX(Datos!$A$1:$K$1,1,RIGHT(Formulas!P4)+2)&IF(Formulas!O4=1," "&Formulas!N4,"")&":","")))} -> Descripción: | N7: {=IF(OR(Formulas!O4=0,Formulas!O4="",RIGHT(Formulas!P4)="0"),"", HYPERLINK("["&Archivo_Nombre&"]Datos!"&LEFT(SUBSTITUTE(ADDRESS(1,RIGHT(Formulas!P4)+2),"$",""))&Formulas!N4+1, IFERROR(INDEX(Datos!$A$2:$K$101,Formulas!N4,RIGHT(Formulas!P4)+2),"")))} -> Tercera reunión con el administrador para revisar el progreso, validar requerimientos pendientes y planificar los siguientes sprints. | O7: {=IF(OR(Formulas!P5=0,Formulas!P5=""),"",HYPERLINK("["&Archivo_Nombre&"]Datos!"&LEFT(SUBSTITUTE(ADDRESS(1,Formulas!P5+2),"$",""))&Formulas!O5+1, IFERROR(INDEX(Datos!$A$2:$K$101,Formulas!O5,Formulas!P5+2),"")))} -> #VALUE! | R7: {=IF(OR(Formulas!T4=0,Formulas!T4="",RIGHT(Formulas!U4)="0"),"", HYPERLINK("["&Archivo_Nombre&"]Datos!"&LEFT(SUBSTITUTE(ADDRESS(1,IF(Formulas!T4=1,1,RIGHT(Formulas!U4)+2)),"$",""))&Formulas!S4+1, IFERROR(INDEX(Datos!$A$1:$K$1,1,RIGHT(Formulas!U4)+2)&IF(Formulas!T4=1," "&Formulas!S4,"")&":","")))} -> Descripción: | S7: {=IF(OR(Formulas!T4=0,Formulas!T4="",RIGHT(Formulas!U4)="0"),"", HYPERLINK("["&Archivo_Nombre&"]Datos!"&LEFT(SUBSTITUTE(ADDRESS(1,RIGHT(Formulas!U4)+2),"$",""))&Formulas!S4+1, IFERROR(INDEX(Datos!$A$2:$K$101,Formulas!S4,RIGHT(Formulas!U4)+2),"")))} -> Exponer los requisitos completados en el sprint al equipo y stakeholders. | T7: {=IF(OR(Formulas!U5=0,Formulas!U5=""),"",HYPERLINK("["&Archivo_Nombre&"]Datos!"&LEFT(SUBSTITUTE(ADDRESS(1,Formulas!U5+2),"$",""))&Formulas!T5+1, IFERROR(INDEX(Datos!$A$2:$K$101,Formulas!T5,Formulas!U5+2),"")))} -> #VALUE! | W7: {=IF(OR(Formulas!Y4=0,Formulas!Y4="",RIGHT(Formulas!Z4)="0"),"", HYPERLINK("["&Archivo_Nombre&"]Datos!"&LEFT(SUBSTITUTE(ADDRESS(1,IF(Formulas!Y4=1,1,RIGHT(Formulas!Z4)+2)),"$",""))&Formulas!X4+1, IFERROR(INDEX(Datos!$A$1:$K$1,1,RIGHT(Formulas!Z4)+2)&IF(Formulas!Y4=1," "&Formulas!X4,"")&":","")))} | X7: {=IF(OR(Formulas!Y4=0,Formulas!Y4="",RIGHT(Formulas!Z4)="0"),"", HYPERLINK("["&Archivo_Nombre&"]Datos!"&LEFT(SUBSTITUTE(ADDRESS(1,RIGHT(Formulas!Z4)+2),"$",""))&Formulas!X4+1, IFERROR(INDEX(Datos!$A$2:$K$101,Formulas!X4,RIGHT(Formulas!Z4)+2),"")))} | Y7: {=IF(OR(Formulas!Z5=0,Formulas!Z5=""),"",HYPERLINK("["&Archivo_Nombre&"]Datos!"&LEFT(SUBSTITUTE(ADDRESS(1,Formulas!Z5+2),"$",""))&Formulas!Y5+1, IFERROR(INDEX(Datos!$A$2:$K$101,Formulas!Y5,Formulas!Z5+2),"")))} | AB7: {=IF(OR(Formulas!AD4=0,Formulas!AD4="",RIGHT(Formulas!AE4)="0"),"", HYPERLINK("["&Archivo_Nombre&"]Datos!"&LEFT(SUBSTITUTE(ADDRESS(1,IF(Formulas!AD4=1,1,RIGHT(Formulas!AE4)+2)),"$",""))&Formulas!AC4+1, IFERROR(INDEX(Datos!$A$1:$K$1,1,RIGHT(Formulas!AE4)+2)&IF(Formulas!AD4=1," "&Formulas!AC4,"")&":","")))} | AC7: {=IF(OR(Formulas!AD4=0,Formulas!AD4="",RIGHT(Formulas!AE4)="0"),"", HYPERLINK("["&Archivo_Nombre&"]Datos!"&LEFT(SUBSTITUTE(ADDRESS(1,RIGHT(Formulas!AE4)+2),"$",""))&Formulas!AC4+1, IFERROR(INDEX(Datos!$A$2:$K$101,Formulas!AC4,RIGHT(Formulas!AE4)+2),"")))} | AD7: {=IF(OR(Formulas!AE5=0,Formulas!AE5=""),"",HYPERLINK("["&Archivo_Nombre&"]Datos!"&LEFT(SUBSTITUTE(ADDRESS(1,Formulas!AE5+2),"$",""))&Formulas!AD5+1, IFERROR(INDEX(Datos!$A$2:$K$101,Formulas!AD5,Formulas!AE5+2),"")))} | AG7: {=IF(OR(Formulas!AI4=0,Formulas!AI4="",RIGHT(Formulas!AJ4)="0"),"", HYPERLINK("["&Archivo_Nombre&"]Datos!"&LEFT(SUBSTITUTE(ADDRESS(1,IF(Formulas!AI4=1,1,RIGHT(Formulas!AJ4)+2)),"$",""))&Formulas!AH4+1, IFERROR(INDEX(Datos!$A$1:$K$1,1,RIGHT(Formulas!AJ4)+2)&IF(Formulas!AI4=1," "&Formulas!AH4,"")&":","")))} | AH7: {=IF(OR(Formulas!AI4=0,Formulas!AI4="",RIGHT(Formulas!AJ4)="0"),"", HYPERLINK("["&Archivo_Nombre&"]Datos!"&LEFT(SUBSTITUTE(ADDRESS(1,RIGHT(Formulas!AJ4)+2),"$",""))&Formulas!AH4+1, IFERROR(INDEX(Datos!$A$2:$K$101,Formulas!AH4,RIGHT(Formulas!AJ4)+2),"")))} | AI7: {=IF(OR(Formulas!AJ5=0,Formulas!AJ5=""),"",HYPERLINK("["&Archivo_Nombre&"]Datos!"&LEFT(SUBSTITUTE(ADDRESS(1,Formulas!AJ5+2),"$",""))&Formulas!AI5+1, IFERROR(INDEX(Datos!$A$2:$K$101,Formulas!AI5,Formulas!AJ5+2),"")))} | AL7: {=IF(OR(Formulas!AN4=0,Formulas!AN4="",RIGHT(Formulas!AO4)="0"),"", HYPERLINK("["&Archivo_Nombre&"]Datos!"&LEFT(SUBSTITUTE(ADDRESS(1,IF(Formulas!AN4=1,1,RIGHT(Formulas!AO4)+2)),"$",""))&Formulas!AM4+1, IFERROR(INDEX(Datos!$A$1:$K$1,1,RIGHT(Formulas!AO4)+2)&IF(Formulas!AN4=1," "&Formulas!AM4,"")&":","")))} | AM7: {=IF(OR(Formulas!AN4=0,Formulas!AN4="",RIGHT(Formulas!AO4)="0"),"", HYPERLINK("["&Archivo_Nombre&"]Datos!"&LEFT(SUBSTITUTE(ADDRESS(1,RIGHT(Formulas!AO4)+2),"$",""))&Formulas!AM4+1, IFERROR(INDEX(Datos!$A$2:$K$101,Formulas!AM4,RIGHT(Formulas!AO4)+2),"")))} | AN7: {=IF(OR(Formulas!AO5=0,Formulas!AO5=""),"",HYPERLINK("["&Archivo_Nombre&"]Datos!"&LEFT(SUBSTITUTE(ADDRESS(1,Formulas!AO5+2),"$",""))&Formulas!AN5+1, IFERROR(INDEX(Datos!$A$2:$K$101,Formulas!AN5,Formulas!AO5+2),"")))} | AQ7: {=IF(OR(Formulas!AS4=0,Formulas!AS4="",RIGHT(Formulas!AT4)="0"),"", HYPERLINK("["&Archivo_Nombre&"]Datos!"&LEFT(SUBSTITUTE(ADDRESS(1,IF(Formulas!AS4=1,1,RIGHT(Formulas!AT4)+2)),"$",""))&Formulas!AR4+1, IFERROR(INDEX(Datos!$A$1:$K$1,1,RIGHT(Formulas!AT4)+2)&IF(Formulas!AS4=1," "&Formulas!AR4,"")&":","")))} | AR7: {=IF(OR(Formulas!AS4=0,Formulas!AS4="",RIGHT(Formulas!AT4)="0"),"", HYPERLINK("["&Archivo_Nombre&"]Datos!"&LEFT(SUBSTITUTE(ADDRESS(1,RIGHT(Formulas!AT4)+2),"$",""))&Formulas!AR4+1, IFERROR(INDEX(Datos!$A$2:$K$101,Formulas!AR4,RIGHT(Formulas!AT4)+2),"")))} | AS7: {=IF(OR(Formulas!AT5=0,Formulas!AT5=""),"",HYPERLINK("["&Archivo_Nombre&"]Datos!"&LEFT(SUBSTITUTE(ADDRESS(1,Formulas!AT5+2),"$",""))&Formulas!AS5+1, IFERROR(INDEX(Datos!$A$2:$K$101,Formulas!AS5,Formulas!AT5+2),"")))} | AV7: {=IF(OR(Formulas!AX4=0,Formulas!AX4="",RIGHT(Formulas!AY4)="0"),"", HYPERLINK("["&Archivo_Nombre&"]Datos!"&LEFT(SUBSTITUTE(ADDRESS(1,IF(Formulas!AX4=1,1,RIGHT(Formulas!AY4)+2)),"$",""))&Formulas!AW4+1, IFERROR(INDEX(Datos!$A$1:$K$1,1,RIGHT(Formulas!AY4)+2)&IF(Formulas!AX4=1," "&Formulas!AW4,"")&":","")))} | AW7: {=IF(OR(Formulas!AX4=0,Formulas!AX4="",RIGHT(Formulas!AY4)="0"),"", HYPERLINK("["&Archivo_Nombre&"]Datos!"&LEFT(SUBSTITUTE(ADDRESS(1,RIGHT(Formulas!AY4)+2),"$",""))&Formulas!AW4+1, IFERROR(INDEX(Datos!$A$2:$K$101,Formulas!AW4,RIGHT(Formulas!AY4)+2),"")))} | AX7: {=IF(OR(Formulas!AY5=0,Formulas!AY5=""),"",HYPERLINK("["&Archivo_Nombre&"]Datos!"&LEFT(SUBSTITUTE(ADDRESS(1,Formulas!AY5+2),"$",""))&Formulas!AX5+1, IFERROR(INDEX(Datos!$A$2:$K$101,Formulas!AX5,Formulas!AY5+2),"")))}
C8: {=IF(OR(Formulas!E5=0,Formulas!E5="",RIGHT(Formulas!F5)="0"),"", HYPERLINK("["&Archivo_Nombre&"]Datos!"&LEFT(SUBSTITUTE(ADDRESS(1,IF(Formulas!E5=1,1,RIGHT(Formulas!F5)+2)),"$",""))&Formulas!D5+1, IFERROR(INDEX(Datos!$A$1:$K$1,1,RIGHT(Formulas!F5)+2)&IF(Formulas!E5=1," "&Formulas!D5,"")&":","")))} -> Inicio: | D8: {=IF(OR(Formulas!E5=0,Formulas!E5="",RIGHT(Formulas!F5)="0"),"", HYPERLINK("["&Archivo_Nombre&"]Datos!"&LEFT(SUBSTITUTE(ADDRESS(1,RIGHT(Formulas!F5)+2),"$",""))&Formulas!D5+1, IFERROR(INDEX(Datos!$A$2:$K$101,Formulas!D5,RIGHT(Formulas!F5)+2),"")))} -> 46185 | E8: {=IF(OR(Formulas!F6=0,Formulas!F6=""),"",HYPERLINK("["&Archivo_Nombre&"]Datos!"&LEFT(SUBSTITUTE(ADDRESS(1,Formulas!F6+2),"$",""))&Formulas!E6+1, IFERROR(INDEX(Datos!$A$2:$K$101,Formulas!E6,Formulas!F6+2),"")))} -> #VALUE! | H8: {=IF(OR(Formulas!J5=0,Formulas!J5="",RIGHT(Formulas!K5)="0"),"", HYPERLINK("["&Archivo_Nombre&"]Datos!"&LEFT(SUBSTITUTE(ADDRESS(1,IF(Formulas!J5=1,1,RIGHT(Formulas!K5)+2)),"$",""))&Formulas!I5+1, IFERROR(INDEX(Datos!$A$1:$K$1,1,RIGHT(Formulas!K5)+2)&IF(Formulas!J5=1," "&Formulas!I5,"")&":","")))} -> Inicio: | I8: {=IF(OR(Formulas!J5=0,Formulas!J5="",RIGHT(Formulas!K5)="0"),"", HYPERLINK("["&Archivo_Nombre&"]Datos!"&LEFT(SUBSTITUTE(ADDRESS(1,RIGHT(Formulas!K5)+2),"$",""))&Formulas!I5+1, IFERROR(INDEX(Datos!$A$2:$K$101,Formulas!I5,RIGHT(Formulas!K5)+2),"")))} -> 46185 | J8: {=IF(OR(Formulas!K6=0,Formulas!K6=""),"",HYPERLINK("["&Archivo_Nombre&"]Datos!"&LEFT(SUBSTITUTE(ADDRESS(1,Formulas!K6+2),"$",""))&Formulas!J6+1, IFERROR(INDEX(Datos!$A$2:$K$101,Formulas!J6,Formulas!K6+2),"")))} -> #VALUE! | M8: {=IF(OR(Formulas!O5=0,Formulas!O5="",RIGHT(Formulas!P5)="0"),"", HYPERLINK("["&Archivo_Nombre&"]Datos!"&LEFT(SUBSTITUTE(ADDRESS(1,IF(Formulas!O5=1,1,RIGHT(Formulas!P5)+2)),"$",""))&Formulas!N5+1, IFERROR(INDEX(Datos!$A$1:$K$1,1,RIGHT(Formulas!P5)+2)&IF(Formulas!O5=1," "&Formulas!N5,"")&":","")))} -> Inicio: | N8: {=IF(OR(Formulas!O5=0,Formulas!O5="",RIGHT(Formulas!P5)="0"),"", HYPERLINK("["&Archivo_Nombre&"]Datos!"&LEFT(SUBSTITUTE(ADDRESS(1,RIGHT(Formulas!P5)+2),"$",""))&Formulas!N5+1, IFERROR(INDEX(Datos!$A$2:$K$101,Formulas!N5,RIGHT(Formulas!P5)+2),"")))} -> 46190 | O8: {=IF(OR(Formulas!P6=0,Formulas!P6=""),"",HYPERLINK("["&Archivo_Nombre&"]Datos!"&LEFT(SUBSTITUTE(ADDRESS(1,Formulas!P6+2),"$",""))&Formulas!O6+1, IFERROR(INDEX(Datos!$A$2:$K$101,Formulas!O6,Formulas!P6+2),"")))} -> #VALUE! | R8: {=IF(OR(Formulas!T5=0,Formulas!T5="",RIGHT(Formulas!U5)="0"),"", HYPERLINK("["&Archivo_Nombre&"]Datos!"&LEFT(SUBSTITUTE(ADDRESS(1,IF(Formulas!T5=1,1,RIGHT(Formulas!U5)+2)),"$",""))&Formulas!S5+1, IFERROR(INDEX(Datos!$A$1:$K$1,1,RIGHT(Formulas!U5)+2)&IF(Formulas!T5=1," "&Formulas!S5,"")&":","")))} -> Inicio: | S8: {=IF(OR(Formulas!T5=0,Formulas!T5="",RIGHT(Formulas!U5)="0"),"", HYPERLINK("["&Archivo_Nombre&"]Datos!"&LEFT(SUBSTITUTE(ADDRESS(1,RIGHT(Formulas!U5)+2),"$",""))&Formulas!S5+1, IFERROR(INDEX(Datos!$A$2:$K$101,Formulas!S5,RIGHT(Formulas!U5)+2),"")))} -> 46177 | T8: {=IF(OR(Formulas!U6=0,Formulas!U6=""),"",HYPERLINK("["&Archivo_Nombre&"]Datos!"&LEFT(SUBSTITUTE(ADDRESS(1,Formulas!U6+2),"$",""))&Formulas!T6+1, IFERROR(INDEX(Datos!$A$2:$K$101,Formulas!T6,Formulas!U6+2),"")))} -> #VALUE! | W8: {=IF(OR(Formulas!Y5=0,Formulas!Y5="",RIGHT(Formulas!Z5)="0"),"", HYPERLINK("["&Archivo_Nombre&"]Datos!"&LEFT(SUBSTITUTE(ADDRESS(1,IF(Formulas!Y5=1,1,RIGHT(Formulas!Z5)+2)),"$",""))&Formulas!X5+1, IFERROR(INDEX(Datos!$A$1:$K$1,1,RIGHT(Formulas!Z5)+2)&IF(Formulas!Y5=1," "&Formulas!X5,"")&":","")))} | X8: {=IF(OR(Formulas!Y5=0,Formulas!Y5="",RIGHT(Formulas!Z5)="0"),"", HYPERLINK("["&Archivo_Nombre&"]Datos!"&LEFT(SUBSTITUTE(ADDRESS(1,RIGHT(Formulas!Z5)+2),"$",""))&Formulas!X5+1, IFERROR(INDEX(Datos!$A$2:$K$101,Formulas!X5,RIGHT(Formulas!Z5)+2),"")))} | Y8: {=IF(OR(Formulas!Z6=0,Formulas!Z6=""),"",HYPERLINK("["&Archivo_Nombre&"]Datos!"&LEFT(SUBSTITUTE(ADDRESS(1,Formulas!Z6+2),"$",""))&Formulas!Y6+1, IFERROR(INDEX(Datos!$A$2:$K$101,Formulas!Y6,Formulas!Z6+2),"")))} | AB8: {=IF(OR(Formulas!AD5=0,Formulas!AD5="",RIGHT(Formulas!AE5)="0"),"", HYPERLINK("["&Archivo_Nombre&"]Datos!"&LEFT(SUBSTITUTE(ADDRESS(1,IF(Formulas!AD5=1,1,RIGHT(Formulas!AE5)+2)),"$",""))&Formulas!AC5+1, IFERROR(INDEX(Datos!$A$1:$K$1,1,RIGHT(Formulas!AE5)+2)&IF(Formulas!AD5=1," "&Formulas!AC5,"")&":","")))} | AC8: {=IF(OR(Formulas!AD5=0,Formulas!AD5="",RIGHT(Formulas!AE5)="0"),"", HYPERLINK("["&Archivo_Nombre&"]Datos!"&LEFT(SUBSTITUTE(ADDRESS(1,RIGHT(Formulas!AE5)+2),"$",""))&Formulas!AC5+1, IFERROR(INDEX(Datos!$A$2:$K$101,Formulas!AC5,RIGHT(Formulas!AE5)+2),"")))} | AD8: {=IF(OR(Formulas!AE6=0,Formulas!AE6=""),"",HYPERLINK("["&Archivo_Nombre&"]Datos!"&LEFT(SUBSTITUTE(ADDRESS(1,Formulas!AE6+2),"$",""))&Formulas!AD6+1, IFERROR(INDEX(Datos!$A$2:$K$101,Formulas!AD6,Formulas!AE6+2),"")))} | AG8: {=IF(OR(Formulas!AI5=0,Formulas!AI5="",RIGHT(Formulas!AJ5)="0"),"", HYPERLINK("["&Archivo_Nombre&"]Datos!"&LEFT(SUBSTITUTE(ADDRESS(1,IF(Formulas!AI5=1,1,RIGHT(Formulas!AJ5)+2)),"$",""))&Formulas!AH5+1, IFERROR(INDEX(Datos!$A$1:$K$1,1,RIGHT(Formulas!AJ5)+2)&IF(Formulas!AI5=1," "&Formulas!AH5,"")&":","")))} | AH8: {=IF(OR(Formulas!AI5=0,Formulas!AI5="",RIGHT(Formulas!AJ5)="0"),"", HYPERLINK("["&Archivo_Nombre&"]Datos!"&LEFT(SUBSTITUTE(ADDRESS(1,RIGHT(Formulas!AJ5)+2),"$",""))&Formulas!AH5+1, IFERROR(INDEX(Datos!$A$2:$K$101,Formulas!AH5,RIGHT(Formulas!AJ5)+2),"")))} | AI8: {=IF(OR(Formulas!AJ6=0,Formulas!AJ6=""),"",HYPERLINK("["&Archivo_Nombre&"]Datos!"&LEFT(SUBSTITUTE(ADDRESS(1,Formulas!AJ6+2),"$",""))&Formulas!AI6+1, IFERROR(INDEX(Datos!$A$2:$K$101,Formulas!AI6,Formulas!AJ6+2),"")))} | AL8: {=IF(OR(Formulas!AN5=0,Formulas!AN5="",RIGHT(Formulas!AO5)="0"),"", HYPERLINK("["&Archivo_Nombre&"]Datos!"&LEFT(SUBSTITUTE(ADDRESS(1,IF(Formulas!AN5=1,1,RIGHT(Formulas!AO5)+2)),"$",""))&Formulas!AM5+1, IFERROR(INDEX(Datos!$A$1:$K$1,1,RIGHT(Formulas!AO5)+2)&IF(Formulas!AN5=1," "&Formulas!AM5,"")&":","")))} | AM8: {=IF(OR(Formulas!AN5=0,Formulas!AN5="",RIGHT(Formulas!AO5)="0"),"", HYPERLINK("["&Archivo_Nombre&"]Datos!"&LEFT(SUBSTITUTE(ADDRESS(1,RIGHT(Formulas!AO5)+2),"$",""))&Formulas!AM5+1, IFERROR(INDEX(Datos!$A$2:$K$101,Formulas!AM5,RIGHT(Formulas!AO5)+2),"")))} | AN8: {=IF(OR(Formulas!AO6=0,Formulas!AO6=""),"",HYPERLINK("["&Archivo_Nombre&"]Datos!"&LEFT(SUBSTITUTE(ADDRESS(1,Formulas!AO6+2),"$",""))&Formulas!AN6+1, IFERROR(INDEX(Datos!$A$2:$K$101,Formulas!AN6,Formulas!AO6+2),"")))} | AQ8: {=IF(OR(Formulas!AS5=0,Formulas!AS5="",RIGHT(Formulas!AT5)="0"),"", HYPERLINK("["&Archivo_Nombre&"]Datos!"&LEFT(SUBSTITUTE(ADDRESS(1,IF(Formulas!AS5=1,1,RIGHT(Formulas!AT5)+2)),"$",""))&Formulas!AR5+1, IFERROR(INDEX(Datos!$A$1:$K$1,1,RIGHT(Formulas!AT5)+2)&IF(Formulas!AS5=1," "&Formulas!AR5,"")&":","")))} | AR8: {=IF(OR(Formulas!AS5=0,Formulas!AS5="",RIGHT(Formulas!AT5)="0"),"", HYPERLINK("["&Archivo_Nombre&"]Datos!"&LEFT(SUBSTITUTE(ADDRESS(1,RIGHT(Formulas!AT5)+2),"$",""))&Formulas!AR5+1, IFERROR(INDEX(Datos!$A$2:$K$101,Formulas!AR5,RIGHT(Formulas!AT5)+2),"")))} | AS8: {=IF(OR(Formulas!AT6=0,Formulas!AT6=""),"",HYPERLINK("["&Archivo_Nombre&"]Datos!"&LEFT(SUBSTITUTE(ADDRESS(1,Formulas!AT6+2),"$",""))&Formulas!AS6+1, IFERROR(INDEX(Datos!$A$2:$K$101,Formulas!AS6,Formulas!AT6+2),"")))} | AV8: {=IF(OR(Formulas!AX5=0,Formulas!AX5="",RIGHT(Formulas!AY5)="0"),"", HYPERLINK("["&Archivo_Nombre&"]Datos!"&LEFT(SUBSTITUTE(ADDRESS(1,IF(Formulas!AX5=1,1,RIGHT(Formulas!AY5)+2)),"$",""))&Formulas!AW5+1, IFERROR(INDEX(Datos!$A$1:$K$1,1,RIGHT(Formulas!AY5)+2)&IF(Formulas!AX5=1," "&Formulas!AW5,"")&":","")))} | AW8: {=IF(OR(Formulas!AX5=0,Formulas!AX5="",RIGHT(Formulas!AY5)="0"),"", HYPERLINK("["&Archivo_Nombre&"]Datos!"&LEFT(SUBSTITUTE(ADDRESS(1,RIGHT(Formulas!AY5)+2),"$",""))&Formulas!AW5+1, IFERROR(INDEX(Datos!$A$2:$K$101,Formulas!AW5,RIGHT(Formulas!AY5)+2),"")))} | AX8: {=IF(OR(Formulas!AY6=0,Formulas!AY6=""),"",HYPERLINK("["&Archivo_Nombre&"]Datos!"&LEFT(SUBSTITUTE(ADDRESS(1,Formulas!AY6+2),"$",""))&Formulas!AX6+1, IFERROR(INDEX(Datos!$A$2:$K$101,Formulas!AX6,Formulas!AY6+2),"")))}
C9: {=IF(OR(Formulas!E6=0,Formulas!E6="",RIGHT(Formulas!F6)="0"),"", HYPERLINK("["&Archivo_Nombre&"]Datos!"&LEFT(SUBSTITUTE(ADDRESS(1,IF(Formulas!E6=1,1,RIGHT(Formulas!F6)+2)),"$",""))&Formulas!D6+1, IFERROR(INDEX(Datos!$A$1:$K$1,1,RIGHT(Formulas!F6)+2)&IF(Formulas!E6=1," "&Formulas!D6,"")&":","")))} -> Previsto: | D9: {=IF(OR(Formulas!E6=0,Formulas!E6="",RIGHT(Formulas!F6)="0"),"", HYPERLINK("["&Archivo_Nombre&"]Datos!"&LEFT(SUBSTITUTE(ADDRESS(1,RIGHT(Formulas!F6)+2),"$",""))&Formulas!D6+1, IFERROR(INDEX(Datos!$A$2:$K$101,Formulas!D6,RIGHT(Formulas!F6)+2),"")))} -> 46186 | E9: {=IF(OR(Formulas!F7=0,Formulas!F7=""),"",HYPERLINK("["&Archivo_Nombre&"]Datos!"&LEFT(SUBSTITUTE(ADDRESS(1,Formulas!F7+2),"$",""))&Formulas!E7+1, IFERROR(INDEX(Datos!$A$2:$K$101,Formulas!E7,Formulas!F7+2),"")))} -> #VALUE! | H9: {=IF(OR(Formulas!J6=0,Formulas!J6="",RIGHT(Formulas!K6)="0"),"", HYPERLINK("["&Archivo_Nombre&"]Datos!"&LEFT(SUBSTITUTE(ADDRESS(1,IF(Formulas!J6=1,1,RIGHT(Formulas!K6)+2)),"$",""))&Formulas!I6+1, IFERROR(INDEX(Datos!$A$1:$K$1,1,RIGHT(Formulas!K6)+2)&IF(Formulas!J6=1," "&Formulas!I6,"")&":","")))} -> Previsto: | I9: {=IF(OR(Formulas!J6=0,Formulas!J6="",RIGHT(Formulas!K6)="0"),"", HYPERLINK("["&Archivo_Nombre&"]Datos!"&LEFT(SUBSTITUTE(ADDRESS(1,RIGHT(Formulas!K6)+2),"$",""))&Formulas!I6+1, IFERROR(INDEX(Datos!$A$2:$K$101,Formulas!I6,RIGHT(Formulas!K6)+2),"")))} -> 46186 | J9: {=IF(OR(Formulas!K7=0,Formulas!K7=""),"",HYPERLINK("["&Archivo_Nombre&"]Datos!"&LEFT(SUBSTITUTE(ADDRESS(1,Formulas!K7+2),"$",""))&Formulas!J7+1, IFERROR(INDEX(Datos!$A$2:$K$101,Formulas!J7,Formulas!K7+2),"")))} -> #VALUE! | M9: {=IF(OR(Formulas!O6=0,Formulas!O6="",RIGHT(Formulas!P6)="0"),"", HYPERLINK("["&Archivo_Nombre&"]Datos!"&LEFT(SUBSTITUTE(ADDRESS(1,IF(Formulas!O6=1,1,RIGHT(Formulas!P6)+2)),"$",""))&Formulas!N6+1, IFERROR(INDEX(Datos!$A$1:$K$1,1,RIGHT(Formulas!P6)+2)&IF(Formulas!O6=1," "&Formulas!N6,"")&":","")))} -> Previsto: | N9: {=IF(OR(Formulas!O6=0,Formulas!O6="",RIGHT(Formulas!P6)="0"),"", HYPERLINK("["&Archivo_Nombre&"]Datos!"&LEFT(SUBSTITUTE(ADDRESS(1,RIGHT(Formulas!P6)+2),"$",""))&Formulas!N6+1, IFERROR(INDEX(Datos!$A$2:$K$101,Formulas!N6,RIGHT(Formulas!P6)+2),"")))} -> 46190 | O9: {=IF(OR(Formulas!P7=0,Formulas!P7=""),"",HYPERLINK("["&Archivo_Nombre&"]Datos!"&LEFT(SUBSTITUTE(ADDRESS(1,Formulas!P7+2),"$",""))&Formulas!O7+1, IFERROR(INDEX(Datos!$A$2:$K$101,Formulas!O7,Formulas!P7+2),"")))} -> #VALUE! | R9: {=IF(OR(Formulas!T6=0,Formulas!T6="",RIGHT(Formulas!U6)="0"),"", HYPERLINK("["&Archivo_Nombre&"]Datos!"&LEFT(SUBSTITUTE(ADDRESS(1,IF(Formulas!T6=1,1,RIGHT(Formulas!U6)+2)),"$",""))&Formulas!S6+1, IFERROR(INDEX(Datos!$A$1:$K$1,1,RIGHT(Formulas!U6)+2)&IF(Formulas!T6=1," "&Formulas!S6,"")&":","")))} -> Previsto: | S9: {=IF(OR(Formulas!T6=0,Formulas!T6="",RIGHT(Formulas!U6)="0"),"", HYPERLINK("["&Archivo_Nombre&"]Datos!"&LEFT(SUBSTITUTE(ADDRESS(1,RIGHT(Formulas!U6)+2),"$",""))&Formulas!S6+1, IFERROR(INDEX(Datos!$A$2:$K$101,Formulas!S6,RIGHT(Formulas!U6)+2),"")))} -> 46177 | T9: {=IF(OR(Formulas!U7=0,Formulas!U7=""),"",HYPERLINK("["&Archivo_Nombre&"]Datos!"&LEFT(SUBSTITUTE(ADDRESS(1,Formulas!U7+2),"$",""))&Formulas!T7+1, IFERROR(INDEX(Datos!$A$2:$K$101,Formulas!T7,Formulas!U7+2),"")))} -> #VALUE! | W9: {=IF(OR(Formulas!Y6=0,Formulas!Y6="",RIGHT(Formulas!Z6)="0"),"", HYPERLINK("["&Archivo_Nombre&"]Datos!"&LEFT(SUBSTITUTE(ADDRESS(1,IF(Formulas!Y6=1,1,RIGHT(Formulas!Z6)+2)),"$",""))&Formulas!X6+1, IFERROR(INDEX(Datos!$A$1:$K$1,1,RIGHT(Formulas!Z6)+2)&IF(Formulas!Y6=1," "&Formulas!X6,"")&":","")))} | X9: {=IF(OR(Formulas!Y6=0,Formulas!Y6="",RIGHT(Formulas!Z6)="0"),"", HYPERLINK("["&Archivo_Nombre&"]Datos!"&LEFT(SUBSTITUTE(ADDRESS(1,RIGHT(Formulas!Z6)+2),"$",""))&Formulas!X6+1, IFERROR(INDEX(Datos!$A$2:$K$101,Formulas!X6,RIGHT(Formulas!Z6)+2),"")))} | Y9: {=IF(OR(Formulas!Z7=0,Formulas!Z7=""),"",HYPERLINK("["&Archivo_Nombre&"]Datos!"&LEFT(SUBSTITUTE(ADDRESS(1,Formulas!Z7+2),"$",""))&Formulas!Y7+1, IFERROR(INDEX(Datos!$A$2:$K$101,Formulas!Y7,Formulas!Z7+2),"")))} | AB9: {=IF(OR(Formulas!AD6=0,Formulas!AD6="",RIGHT(Formulas!AE6)="0"),"", HYPERLINK("["&Archivo_Nombre&"]Datos!"&LEFT(SUBSTITUTE(ADDRESS(1,IF(Formulas!AD6=1,1,RIGHT(Formulas!AE6)+2)),"$",""))&Formulas!AC6+1, IFERROR(INDEX(Datos!$A$1:$K$1,1,RIGHT(Formulas!AE6)+2)&IF(Formulas!AD6=1," "&Formulas!AC6,"")&":","")))} | AC9: {=IF(OR(Formulas!AD6=0,Formulas!AD6="",RIGHT(Formulas!AE6)="0"),"", HYPERLINK("["&Archivo_Nombre&"]Datos!"&LEFT(SUBSTITUTE(ADDRESS(1,RIGHT(Formulas!AE6)+2),"$",""))&Formulas!AC6+1, IFERROR(INDEX(Datos!$A$2:$K$101,Formulas!AC6,RIGHT(Formulas!AE6)+2),"")))} | AD9: {=IF(OR(Formulas!AE7=0,Formulas!AE7=""),"",HYPERLINK("["&Archivo_Nombre&"]Datos!"&LEFT(SUBSTITUTE(ADDRESS(1,Formulas!AE7+2),"$",""))&Formulas!AD7+1, IFERROR(INDEX(Datos!$A$2:$K$101,Formulas!AD7,Formulas!AE7+2),"")))} | AG9: {=IF(OR(Formulas!AI6=0,Formulas!AI6="",RIGHT(Formulas!AJ6)="0"),"", HYPERLINK("["&Archivo_Nombre&"]Datos!"&LEFT(SUBSTITUTE(ADDRESS(1,IF(Formulas!AI6=1,1,RIGHT(Formulas!AJ6)+2)),"$",""))&Formulas!AH6+1, IFERROR(INDEX(Datos!$A$1:$K$1,1,RIGHT(Formulas!AJ6)+2)&IF(Formulas!AI6=1," "&Formulas!AH6,"")&":","")))} | AH9: {=IF(OR(Formulas!AI6=0,Formulas!AI6="",RIGHT(Formulas!AJ6)="0"),"", HYPERLINK("["&Archivo_Nombre&"]Datos!"&LEFT(SUBSTITUTE(ADDRESS(1,RIGHT(Formulas!AJ6)+2),"$",""))&Formulas!AH6+1, IFERROR(INDEX(Datos!$A$2:$K$101,Formulas!AH6,RIGHT(Formulas!AJ6)+2),"")))} | AI9: {=IF(OR(Formulas!AJ7=0,Formulas!AJ7=""),"",HYPERLINK("["&Archivo_Nombre&"]Datos!"&LEFT(SUBSTITUTE(ADDRESS(1,Formulas!AJ7+2),"$",""))&Formulas!AI7+1, IFERROR(INDEX(Datos!$A$2:$K$101,Formulas!AI7,Formulas!AJ7+2),"")))} | AL9: {=IF(OR(Formulas!AN6=0,Formulas!AN6="",RIGHT(Formulas!AO6)="0"),"", HYPERLINK("["&Archivo_Nombre&"]Datos!"&LEFT(SUBSTITUTE(ADDRESS(1,IF(Formulas!AN6=1,1,RIGHT(Formulas!AO6)+2)),"$",""))&Formulas!AM6+1, IFERROR(INDEX(Datos!$A$1:$K$1,1,RIGHT(Formulas!AO6)+2)&IF(Formulas!AN6=1," "&Formulas!AM6,"")&":","")))} | AM9: {=IF(OR(Formulas!AN6=0,Formulas!AN6="",RIGHT(Formulas!AO6)="0"),"", HYPERLINK("["&Archivo_Nombre&"]Datos!"&LEFT(SUBSTITUTE(ADDRESS(1,RIGHT(Formulas!AO6)+2),"$",""))&Formulas!AM6+1, IFERROR(INDEX(Datos!$A$2:$K$101,Formulas!AM6,RIGHT(Formulas!AO6)+2),"")))} | AN9: {=IF(OR(Formulas!AO7=0,Formulas!AO7=""),"",HYPERLINK("["&Archivo_Nombre&"]Datos!"&LEFT(SUBSTITUTE(ADDRESS(1,Formulas!AO7+2),"$",""))&Formulas!AN7+1, IFERROR(INDEX(Datos!$A$2:$K$101,Formulas!AN7,Formulas!AO7+2),"")))} | AQ9: {=IF(OR(Formulas!AS6=0,Formulas!AS6="",RIGHT(Formulas!AT6)="0"),"", HYPERLINK("["&Archivo_Nombre&"]Datos!"&LEFT(SUBSTITUTE(ADDRESS(1,IF(Formulas!AS6=1,1,RIGHT(Formulas!AT6)+2)),"$",""))&Formulas!AR6+1, IFERROR(INDEX(Datos!$A$1:$K$1,1,RIGHT(Formulas!AT6)+2)&IF(Formulas!AS6=1," "&Formulas!AR6,"")&":","")))} | AR9: {=IF(OR(Formulas!AS6=0,Formulas!AS6="",RIGHT(Formulas!AT6)="0"),"", HYPERLINK("["&Archivo_Nombre&"]Datos!"&LEFT(SUBSTITUTE(ADDRESS(1,RIGHT(Formulas!AT6)+2),"$",""))&Formulas!AR6+1, IFERROR(INDEX(Datos!$A$2:$K$101,Formulas!AR6,RIGHT(Formulas!AT6)+2),"")))} | AS9: {=IF(OR(Formulas!AT7=0,Formulas!AT7=""),"",HYPERLINK("["&Archivo_Nombre&"]Datos!"&LEFT(SUBSTITUTE(ADDRESS(1,Formulas!AT7+2),"$",""))&Formulas!AS7+1, IFERROR(INDEX(Datos!$A$2:$K$101,Formulas!AS7,Formulas!AT7+2),"")))} | AV9: {=IF(OR(Formulas!AX6=0,Formulas!AX6="",RIGHT(Formulas!AY6)="0"),"", HYPERLINK("["&Archivo_Nombre&"]Datos!"&LEFT(SUBSTITUTE(ADDRESS(1,IF(Formulas!AX6=1,1,RIGHT(Formulas!AY6)+2)),"$",""))&Formulas!AW6+1, IFERROR(INDEX(Datos!$A$1:$K$1,1,RIGHT(Formulas!AY6)+2)&IF(Formulas!AX6=1," "&Formulas!AW6,"")&":","")))} | AW9: {=IF(OR(Formulas!AX6=0,Formulas!AX6="",RIGHT(Formulas!AY6)="0"),"", HYPERLINK("["&Archivo_Nombre&"]Datos!"&LEFT(SUBSTITUTE(ADDRESS(1,RIGHT(Formulas!AY6)+2),"$",""))&Formulas!AW6+1, IFERROR(INDEX(Datos!$A$2:$K$101,Formulas!AW6,RIGHT(Formulas!AY6)+2),"")))} | AX9: {=IF(OR(Formulas!AY7=0,Formulas!AY7=""),"",HYPERLINK("["&Archivo_Nombre&"]Datos!"&LEFT(SUBSTITUTE(ADDRESS(1,Formulas!AY7+2),"$",""))&Formulas!AX7+1, IFERROR(INDEX(Datos!$A$2:$K$101,Formulas!AX7,Formulas!AY7+2),"")))}
C10: {=IF(OR(Formulas!E7=0,Formulas!E7="",RIGHT(Formulas!F7)="0"),"", HYPERLINK("["&Archivo_Nombre&"]Datos!"&LEFT(SUBSTITUTE(ADDRESS(1,IF(Formulas!E7=1,1,RIGHT(Formulas!F7)+2)),"$",""))&Formulas!D7+1, IFERROR(INDEX(Datos!$A$1:$K$1,1,RIGHT(Formulas!F7)+2)&IF(Formulas!E7=1," "&Formulas!D7,"")&":","")))} -> Final: | D10: {=IF(OR(Formulas!E7=0,Formulas!E7="",RIGHT(Formulas!F7)="0"),"", HYPERLINK("["&Archivo_Nombre&"]Datos!"&LEFT(SUBSTITUTE(ADDRESS(1,RIGHT(Formulas!F7)+2),"$",""))&Formulas!D7+1, IFERROR(INDEX(Datos!$A$2:$K$101,Formulas!D7,RIGHT(Formulas!F7)+2),"")))} -> 46187 | E10: {=IF(OR(Formulas!F8=0,Formulas!F8=""),"",HYPERLINK("["&Archivo_Nombre&"]Datos!"&LEFT(SUBSTITUTE(ADDRESS(1,Formulas!F8+2),"$",""))&Formulas!E8+1, IFERROR(INDEX(Datos!$A$2:$K$101,Formulas!E8,Formulas!F8+2),"")))} -> #VALUE! | H10: {=IF(OR(Formulas!J7=0,Formulas!J7="",RIGHT(Formulas!K7)="0"),"", HYPERLINK("["&Archivo_Nombre&"]Datos!"&LEFT(SUBSTITUTE(ADDRESS(1,IF(Formulas!J7=1,1,RIGHT(Formulas!K7)+2)),"$",""))&Formulas!I7+1, IFERROR(INDEX(Datos!$A$1:$K$1,1,RIGHT(Formulas!K7)+2)&IF(Formulas!J7=1," "&Formulas!I7,"")&":","")))} -> Final: | I10: {=IF(OR(Formulas!J7=0,Formulas!J7="",RIGHT(Formulas!K7)="0"),"", HYPERLINK("["&Archivo_Nombre&"]Datos!"&LEFT(SUBSTITUTE(ADDRESS(1,RIGHT(Formulas!K7)+2),"$",""))&Formulas!I7+1, IFERROR(INDEX(Datos!$A$2:$K$101,Formulas!I7,RIGHT(Formulas!K7)+2),"")))} -> 46187 | J10: {=IF(OR(Formulas!K8=0,Formulas!K8=""),"",HYPERLINK("["&Archivo_Nombre&"]Datos!"&LEFT(SUBSTITUTE(ADDRESS(1,Formulas!K8+2),"$",""))&Formulas!J8+1, IFERROR(INDEX(Datos!$A$2:$K$101,Formulas!J8,Formulas!K8+2),"")))} -> #VALUE! | M10: {=IF(OR(Formulas!O7=0,Formulas!O7="",RIGHT(Formulas!P7)="0"),"", HYPERLINK("["&Archivo_Nombre&"]Datos!"&LEFT(SUBSTITUTE(ADDRESS(1,IF(Formulas!O7=1,1,RIGHT(Formulas!P7)+2)),"$",""))&Formulas!N7+1, IFERROR(INDEX(Datos!$A$1:$K$1,1,RIGHT(Formulas!P7)+2)&IF(Formulas!O7=1," "&Formulas!N7,"")&":","")))} -> Final: | N10: {=IF(OR(Formulas!O7=0,Formulas!O7="",RIGHT(Formulas!P7)="0"),"", HYPERLINK("["&Archivo_Nombre&"]Datos!"&LEFT(SUBSTITUTE(ADDRESS(1,RIGHT(Formulas!P7)+2),"$",""))&Formulas!N7+1, IFERROR(INDEX(Datos!$A$2:$K$101,Formulas!N7,RIGHT(Formulas!P7)+2),"")))} -> 46190 | O10: {=IF(OR(Formulas!P8=0,Formulas!P8=""),"",HYPERLINK("["&Archivo_Nombre&"]Datos!"&LEFT(SUBSTITUTE(ADDRESS(1,Formulas!P8+2),"$",""))&Formulas!O8+1, IFERROR(INDEX(Datos!$A$2:$K$101,Formulas!O8,Formulas!P8+2),"")))} -> #VALUE! | R10: {=IF(OR(Formulas!T7=0,Formulas!T7="",RIGHT(Formulas!U7)="0"),"", HYPERLINK("["&Archivo_Nombre&"]Datos!"&LEFT(SUBSTITUTE(ADDRESS(1,IF(Formulas!T7=1,1,RIGHT(Formulas!U7)+2)),"$",""))&Formulas!S7+1, IFERROR(INDEX(Datos!$A$1:$K$1,1,RIGHT(Formulas!U7)+2)&IF(Formulas!T7=1," "&Formulas!S7,"")&":","")))} -> Final: | S10: {=IF(OR(Formulas!T7=0,Formulas!T7="",RIGHT(Formulas!U7)="0"),"", HYPERLINK("["&Archivo_Nombre&"]Datos!"&LEFT(SUBSTITUTE(ADDRESS(1,RIGHT(Formulas!U7)+2),"$",""))&Formulas!S7+1, IFERROR(INDEX(Datos!$A$2:$K$101,Formulas!S7,RIGHT(Formulas!U7)+2),"")))} -> 46177 | T10: {=IF(OR(Formulas!U8=0,Formulas!U8=""),"",HYPERLINK("["&Archivo_Nombre&"]Datos!"&LEFT(SUBSTITUTE(ADDRESS(1,Formulas!U8+2),"$",""))&Formulas!T8+1, IFERROR(INDEX(Datos!$A$2:$K$101,Formulas!T8,Formulas!U8+2),"")))} -> #VALUE! | W10: {=IF(OR(Formulas!Y7=0,Formulas!Y7="",RIGHT(Formulas!Z7)="0"),"", HYPERLINK("["&Archivo_Nombre&"]Datos!"&LEFT(SUBSTITUTE(ADDRESS(1,IF(Formulas!Y7=1,1,RIGHT(Formulas!Z7)+2)),"$",""))&Formulas!X7+1, IFERROR(INDEX(Datos!$A$1:$K$1,1,RIGHT(Formulas!Z7)+2)&IF(Formulas!Y7=1," "&Formulas!X7,"")&":","")))} | X10: {=IF(OR(Formulas!Y7=0,Formulas!Y7="",RIGHT(Formulas!Z7)="0"),"", HYPERLINK("["&Archivo_Nombre&"]Datos!"&LEFT(SUBSTITUTE(ADDRESS(1,RIGHT(Formulas!Z7)+2),"$",""))&Formulas!X7+1, IFERROR(INDEX(Datos!$A$2:$K$101,Formulas!X7,RIGHT(Formulas!Z7)+2),"")))} | Y10: {=IF(OR(Formulas!Z8=0,Formulas!Z8=""),"",HYPERLINK("["&Archivo_Nombre&"]Datos!"&LEFT(SUBSTITUTE(ADDRESS(1,Formulas!Z8+2),"$",""))&Formulas!Y8+1, IFERROR(INDEX(Datos!$A$2:$K$101,Formulas!Y8,Formulas!Z8+2),"")))} | AB10: {=IF(OR(Formulas!AD7=0,Formulas!AD7="",RIGHT(Formulas!AE7)="0"),"", HYPERLINK("["&Archivo_Nombre&"]Datos!"&LEFT(SUBSTITUTE(ADDRESS(1,IF(Formulas!AD7=1,1,RIGHT(Formulas!AE7)+2)),"$",""))&Formulas!AC7+1, IFERROR(INDEX(Datos!$A$1:$K$1,1,RIGHT(Formulas!AE7)+2)&IF(Formulas!AD7=1," "&Formulas!AC7,"")&":","")))} | AC10: {=IF(OR(Formulas!AD7=0,Formulas!AD7="",RIGHT(Formulas!AE7)="0"),"", HYPERLINK("["&Archivo_Nombre&"]Datos!"&LEFT(SUBSTITUTE(ADDRESS(1,RIGHT(Formulas!AE7)+2),"$",""))&Formulas!AC7+1, IFERROR(INDEX(Datos!$A$2:$K$101,Formulas!AC7,RIGHT(Formulas!AE7)+2),"")))} | AD10: {=IF(OR(Formulas!AE8=0,Formulas!AE8=""),"",HYPERLINK("["&Archivo_Nombre&"]Datos!"&LEFT(SUBSTITUTE(ADDRESS(1,Formulas!AE8+2),"$",""))&Formulas!AD8+1, IFERROR(INDEX(Datos!$A$2:$K$101,Formulas!AD8,Formulas!AE8+2),"")))} | AG10: {=IF(OR(Formulas!AI7=0,Formulas!AI7="",RIGHT(Formulas!AJ7)="0"),"", HYPERLINK("["&Archivo_Nombre&"]Datos!"&LEFT(SUBSTITUTE(ADDRESS(1,IF(Formulas!AI7=1,1,RIGHT(Formulas!AJ7)+2)),"$",""))&Formulas!AH7+1, IFERROR(INDEX(Datos!$A$1:$K$1,1,RIGHT(Formulas!AJ7)+2)&IF(Formulas!AI7=1," "&Formulas!AH7,"")&":","")))} | AH10: {=IF(OR(Formulas!AI7=0,Formulas!AI7="",RIGHT(Formulas!AJ7)="0"),"", HYPERLINK("["&Archivo_Nombre&"]Datos!"&LEFT(SUBSTITUTE(ADDRESS(1,RIGHT(Formulas!AJ7)+2),"$",""))&Formulas!AH7+1, IFERROR(INDEX(Datos!$A$2:$K$101,Formulas!AH7,RIGHT(Formulas!AJ7)+2),"")))} | AI10: {=IF(OR(Formulas!AJ8=0,Formulas!AJ8=""),"",HYPERLINK("["&Archivo_Nombre&"]Datos!"&LEFT(SUBSTITUTE(ADDRESS(1,Formulas!AJ8+2),"$",""))&Formulas!AI8+1, IFERROR(INDEX(Datos!$A$2:$K$101,Formulas!AI8,Formulas!AJ8+2),"")))} | AL10: {=IF(OR(Formulas!AN7=0,Formulas!AN7="",RIGHT(Formulas!AO7)="0"),"", HYPERLINK("["&Archivo_Nombre&"]Datos!"&LEFT(SUBSTITUTE(ADDRESS(1,IF(Formulas!AN7=1,1,RIGHT(Formulas!AO7)+2)),"$",""))&Formulas!AM7+1, IFERROR(INDEX(Datos!$A$1:$K$1,1,RIGHT(Formulas!AO7)+2)&IF(Formulas!AN7=1," "&Formulas!AM7,"")&":","")))} | AM10: {=IF(OR(Formulas!AN7=0,Formulas!AN7="",RIGHT(Formulas!AO7)="0"),"", HYPERLINK("["&Archivo_Nombre&"]Datos!"&LEFT(SUBSTITUTE(ADDRESS(1,RIGHT(Formulas!AO7)+2),"$",""))&Formulas!AM7+1, IFERROR(INDEX(Datos!$A$2:$K$101,Formulas!AM7,RIGHT(Formulas!AO7)+2),"")))} | AN10: {=IF(OR(Formulas!AO8=0,Formulas!AO8=""),"",HYPERLINK("["&Archivo_Nombre&"]Datos!"&LEFT(SUBSTITUTE(ADDRESS(1,Formulas!AO8+2),"$",""))&Formulas!AN8+1, IFERROR(INDEX(Datos!$A$2:$K$101,Formulas!AN8,Formulas!AO8+2),"")))} | AQ10: {=IF(OR(Formulas!AS7=0,Formulas!AS7="",RIGHT(Formulas!AT7)="0"),"", HYPERLINK("["&Archivo_Nombre&"]Datos!"&LEFT(SUBSTITUTE(ADDRESS(1,IF(Formulas!AS7=1,1,RIGHT(Formulas!AT7)+2)),"$",""))&Formulas!AR7+1, IFERROR(INDEX(Datos!$A$1:$K$1,1,RIGHT(Formulas!AT7)+2)&IF(Formulas!AS7=1," "&Formulas!AR7,"")&":","")))} | AR10: {=IF(OR(Formulas!AS7=0,Formulas!AS7="",RIGHT(Formulas!AT7)="0"),"", HYPERLINK("["&Archivo_Nombre&"]Datos!"&LEFT(SUBSTITUTE(ADDRESS(1,RIGHT(Formulas!AT7)+2),"$",""))&Formulas!AR7+1, IFERROR(INDEX(Datos!$A$2:$K$101,Formulas!AR7,RIGHT(Formulas!AT7)+2),"")))} | AS10: {=IF(OR(Formulas!AT8=0,Formulas!AT8=""),"",HYPERLINK("["&Archivo_Nombre&"]Datos!"&LEFT(SUBSTITUTE(ADDRESS(1,Formulas!AT8+2),"$",""))&Formulas!AS8+1, IFERROR(INDEX(Datos!$A$2:$K$101,Formulas!AS8,Formulas!AT8+2),"")))} | AV10: {=IF(OR(Formulas!AX7=0,Formulas!AX7="",RIGHT(Formulas!AY7)="0"),"", HYPERLINK("["&Archivo_Nombre&"]Datos!"&LEFT(SUBSTITUTE(ADDRESS(1,IF(Formulas!AX7=1,1,RIGHT(Formulas!AY7)+2)),"$",""))&Formulas!AW7+1, IFERROR(INDEX(Datos!$A$1:$K$1,1,RIGHT(Formulas!AY7)+2)&IF(Formulas!AX7=1," "&Formulas!AW7,"")&":","")))} | AW10: {=IF(OR(Formulas!AX7=0,Formulas!AX7="",RIGHT(Formulas!AY7)="0"),"", HYPERLINK("["&Archivo_Nombre&"]Datos!"&LEFT(SUBSTITUTE(ADDRESS(1,RIGHT(Formulas!AY7)+2),"$",""))&Formulas!AW7+1, IFERROR(INDEX(Datos!$A$2:$K$101,Formulas!AW7,RIGHT(Formulas!AY7)+2),"")))} | AX10: {=IF(OR(Formulas!AY8=0,Formulas!AY8=""),"",HYPERLINK("["&Archivo_Nombre&"]Datos!"&LEFT(SUBSTITUTE(ADDRESS(1,Formulas!AY8+2),"$",""))&Formulas!AX8+1, IFERROR(INDEX(Datos!$A$2:$K$101,Formulas!AX8,Formulas!AY8+2),"")))}
C11: {=IF(OR(Formulas!E8=0,Formulas!E8="",RIGHT(Formulas!F8)="0"),"", HYPERLINK("["&Archivo_Nombre&"]Datos!"&LEFT(SUBSTITUTE(ADDRESS(1,IF(Formulas!E8=1,1,RIGHT(Formulas!F8)+2)),"$",""))&Formulas!D8+1, IFERROR(INDEX(Datos!$A$1:$K$1,1,RIGHT(Formulas!F8)+2)&IF(Formulas!E8=1," "&Formulas!D8,"")&":","")))} -> Duración: | D11: {=IF(OR(Formulas!E8=0,Formulas!E8="",RIGHT(Formulas!F8)="0"),"", HYPERLINK("["&Archivo_Nombre&"]Datos!"&LEFT(SUBSTITUTE(ADDRESS(1,RIGHT(Formulas!F8)+2),"$",""))&Formulas!D8+1, IFERROR(INDEX(Datos!$A$2:$K$101,Formulas!D8,RIGHT(Formulas!F8)+2),"")))} -> 3 días | E11: {=IF(OR(Formulas!F9=0,Formulas!F9=""),"",HYPERLINK("["&Archivo_Nombre&"]Datos!"&LEFT(SUBSTITUTE(ADDRESS(1,Formulas!F9+2),"$",""))&Formulas!E9+1, IFERROR(INDEX(Datos!$A$2:$K$101,Formulas!E9,Formulas!F9+2),"")))} -> #VALUE! | H11: {=IF(OR(Formulas!J8=0,Formulas!J8="",RIGHT(Formulas!K8)="0"),"", HYPERLINK("["&Archivo_Nombre&"]Datos!"&LEFT(SUBSTITUTE(ADDRESS(1,IF(Formulas!J8=1,1,RIGHT(Formulas!K8)+2)),"$",""))&Formulas!I8+1, IFERROR(INDEX(Datos!$A$1:$K$1,1,RIGHT(Formulas!K8)+2)&IF(Formulas!J8=1," "&Formulas!I8,"")&":","")))} -> Duración: | I11: {=IF(OR(Formulas!J8=0,Formulas!J8="",RIGHT(Formulas!K8)="0"),"", HYPERLINK("["&Archivo_Nombre&"]Datos!"&LEFT(SUBSTITUTE(ADDRESS(1,RIGHT(Formulas!K8)+2),"$",""))&Formulas!I8+1, IFERROR(INDEX(Datos!$A$2:$K$101,Formulas!I8,RIGHT(Formulas!K8)+2),"")))} -> 3 días | J11: {=IF(OR(Formulas!K9=0,Formulas!K9=""),"",HYPERLINK("["&Archivo_Nombre&"]Datos!"&LEFT(SUBSTITUTE(ADDRESS(1,Formulas!K9+2),"$",""))&Formulas!J9+1, IFERROR(INDEX(Datos!$A$2:$K$101,Formulas!J9,Formulas!K9+2),"")))} -> #VALUE! | M11: {=IF(OR(Formulas!O8=0,Formulas!O8="",RIGHT(Formulas!P8)="0"),"", HYPERLINK("["&Archivo_Nombre&"]Datos!"&LEFT(SUBSTITUTE(ADDRESS(1,IF(Formulas!O8=1,1,RIGHT(Formulas!P8)+2)),"$",""))&Formulas!N8+1, IFERROR(INDEX(Datos!$A$1:$K$1,1,RIGHT(Formulas!P8)+2)&IF(Formulas!O8=1," "&Formulas!N8,"")&":","")))} -> Duración: | N11: {=IF(OR(Formulas!O8=0,Formulas!O8="",RIGHT(Formulas!P8)="0"),"", HYPERLINK("["&Archivo_Nombre&"]Datos!"&LEFT(SUBSTITUTE(ADDRESS(1,RIGHT(Formulas!P8)+2),"$",""))&Formulas!N8+1, IFERROR(INDEX(Datos!$A$2:$K$101,Formulas!N8,RIGHT(Formulas!P8)+2),"")))} -> 1 días | O11: {=IF(OR(Formulas!P9=0,Formulas!P9=""),"",HYPERLINK("["&Archivo_Nombre&"]Datos!"&LEFT(SUBSTITUTE(ADDRESS(1,Formulas!P9+2),"$",""))&Formulas!O9+1, IFERROR(INDEX(Datos!$A$2:$K$101,Formulas!O9,Formulas!P9+2),"")))} -> #VALUE! | R11: {=IF(OR(Formulas!T8=0,Formulas!T8="",RIGHT(Formulas!U8)="0"),"", HYPERLINK("["&Archivo_Nombre&"]Datos!"&LEFT(SUBSTITUTE(ADDRESS(1,IF(Formulas!T8=1,1,RIGHT(Formulas!U8)+2)),"$",""))&Formulas!S8+1, IFERROR(INDEX(Datos!$A$1:$K$1,1,RIGHT(Formulas!U8)+2)&IF(Formulas!T8=1," "&Formulas!S8,"")&":","")))} -> Duración: | S11: {=IF(OR(Formulas!T8=0,Formulas!T8="",RIGHT(Formulas!U8)="0"),"", HYPERLINK("["&Archivo_Nombre&"]Datos!"&LEFT(SUBSTITUTE(ADDRESS(1,RIGHT(Formulas!U8)+2),"$",""))&Formulas!S8+1, IFERROR(INDEX(Datos!$A$2:$K$101,Formulas!S8,RIGHT(Formulas!U8)+2),"")))} -> 1 días | T11: {=IF(OR(Formulas!U9=0,Formulas!U9=""),"",HYPERLINK("["&Archivo_Nombre&"]Datos!"&LEFT(SUBSTITUTE(ADDRESS(1,Formulas!U9+2),"$",""))&Formulas!T9+1, IFERROR(INDEX(Datos!$A$2:$K$101,Formulas!T9,Formulas!U9+2),"")))} -> #VALUE! | W11: {=IF(OR(Formulas!Y8=0,Formulas!Y8="",RIGHT(Formulas!Z8)="0"),"", HYPERLINK("["&Archivo_Nombre&"]Datos!"&LEFT(SUBSTITUTE(ADDRESS(1,IF(Formulas!Y8=1,1,RIGHT(Formulas!Z8)+2)),"$",""))&Formulas!X8+1, IFERROR(INDEX(Datos!$A$1:$K$1,1,RIGHT(Formulas!Z8)+2)&IF(Formulas!Y8=1," "&Formulas!X8,"")&":","")))} | X11: {=IF(OR(Formulas!Y8=0,Formulas!Y8="",RIGHT(Formulas!Z8)="0"),"", HYPERLINK("["&Archivo_Nombre&"]Datos!"&LEFT(SUBSTITUTE(ADDRESS(1,RIGHT(Formulas!Z8)+2),"$",""))&Formulas!X8+1, IFERROR(INDEX(Datos!$A$2:$K$101,Formulas!X8,RIGHT(Formulas!Z8)+2),"")))} | Y11: {=IF(OR(Formulas!Z9=0,Formulas!Z9=""),"",HYPERLINK("["&Archivo_Nombre&"]Datos!"&LEFT(SUBSTITUTE(ADDRESS(1,Formulas!Z9+2),"$",""))&Formulas!Y9+1, IFERROR(INDEX(Datos!$A$2:$K$101,Formulas!Y9,Formulas!Z9+2),"")))} | AB11: {=IF(OR(Formulas!AD8=0,Formulas!AD8="",RIGHT(Formulas!AE8)="0"),"", HYPERLINK("["&Archivo_Nombre&"]Datos!"&LEFT(SUBSTITUTE(ADDRESS(1,IF(Formulas!AD8=1,1,RIGHT(Formulas!AE8)+2)),"$",""))&Formulas!AC8+1, IFERROR(INDEX(Datos!$A$1:$K$1,1,RIGHT(Formulas!AE8)+2)&IF(Formulas!AD8=1," "&Formulas!AC8,"")&":","")))} | AC11: {=IF(OR(Formulas!AD8=0,Formulas!AD8="",RIGHT(Formulas!AE8)="0"),"", HYPERLINK("["&Archivo_Nombre&"]Datos!"&LEFT(SUBSTITUTE(ADDRESS(1,RIGHT(Formulas!AE8)+2),"$",""))&Formulas!AC8+1, IFERROR(INDEX(Datos!$A$2:$K$101,Formulas!AC8,RIGHT(Formulas!AE8)+2),"")))} | AD11: {=IF(OR(Formulas!AE9=0,Formulas!AE9=""),"",HYPERLINK("["&Archivo_Nombre&"]Datos!"&LEFT(SUBSTITUTE(ADDRESS(1,Formulas!AE9+2),"$",""))&Formulas!AD9+1, IFERROR(INDEX(Datos!$A$2:$K$101,Formulas!AD9,Formulas!AE9+2),"")))} | AG11: {=IF(OR(Formulas!AI8=0,Formulas!AI8="",RIGHT(Formulas!AJ8)="0"),"", HYPERLINK("["&Archivo_Nombre&"]Datos!"&LEFT(SUBSTITUTE(ADDRESS(1,IF(Formulas!AI8=1,1,RIGHT(Formulas!AJ8)+2)),"$",""))&Formulas!AH8+1, IFERROR(INDEX(Datos!$A$1:$K$1,1,RIGHT(Formulas!AJ8)+2)&IF(Formulas!AI8=1," "&Formulas!AH8,"")&":","")))} | AH11: {=IF(OR(Formulas!AI8=0,Formulas!AI8="",RIGHT(Formulas!AJ8)="0"),"", HYPERLINK("["&Archivo_Nombre&"]Datos!"&LEFT(SUBSTITUTE(ADDRESS(1,RIGHT(Formulas!AJ8)+2),"$",""))&Formulas!AH8+1, IFERROR(INDEX(Datos!$A$2:$K$101,Formulas!AH8,RIGHT(Formulas!AJ8)+2),"")))} | AI11: {=IF(OR(Formulas!AJ9=0,Formulas!AJ9=""),"",HYPERLINK("["&Archivo_Nombre&"]Datos!"&LEFT(SUBSTITUTE(ADDRESS(1,Formulas!AJ9+2),"$",""))&Formulas!AI9+1, IFERROR(INDEX(Datos!$A$2:$K$101,Formulas!AI9,Formulas!AJ9+2),"")))} | AL11: {=IF(OR(Formulas!AN8=0,Formulas!AN8="",RIGHT(Formulas!AO8)="0"),"", HYPERLINK("["&Archivo_Nombre&"]Datos!"&LEFT(SUBSTITUTE(ADDRESS(1,IF(Formulas!AN8=1,1,RIGHT(Formulas!AO8)+2)),"$",""))&Formulas!AM8+1, IFERROR(INDEX(Datos!$A$1:$K$1,1,RIGHT(Formulas!AO8)+2)&IF(Formulas!AN8=1," "&Formulas!AM8,"")&":","")))} | AM11: {=IF(OR(Formulas!AN8=0,Formulas!AN8="",RIGHT(Formulas!AO8)="0"),"", HYPERLINK("["&Archivo_Nombre&"]Datos!"&LEFT(SUBSTITUTE(ADDRESS(1,RIGHT(Formulas!AO8)+2),"$",""))&Formulas!AM8+1, IFERROR(INDEX(Datos!$A$2:$K$101,Formulas!AM8,RIGHT(Formulas!AO8)+2),"")))} | AN11: {=IF(OR(Formulas!AO9=0,Formulas!AO9=""),"",HYPERLINK("["&Archivo_Nombre&"]Datos!"&LEFT(SUBSTITUTE(ADDRESS(1,Formulas!AO9+2),"$",""))&Formulas!AN9+1, IFERROR(INDEX(Datos!$A$2:$K$101,Formulas!AN9,Formulas!AO9+2),"")))} | AQ11: {=IF(OR(Formulas!AS8=0,Formulas!AS8="",RIGHT(Formulas!AT8)="0"),"", HYPERLINK("["&Archivo_Nombre&"]Datos!"&LEFT(SUBSTITUTE(ADDRESS(1,IF(Formulas!AS8=1,1,RIGHT(Formulas!AT8)+2)),"$",""))&Formulas!AR8+1, IFERROR(INDEX(Datos!$A$1:$K$1,1,RIGHT(Formulas!AT8)+2)&IF(Formulas!AS8=1," "&Formulas!AR8,"")&":","")))} | AR11: {=IF(OR(Formulas!AS8=0,Formulas!AS8="",RIGHT(Formulas!AT8)="0"),"", HYPERLINK("["&Archivo_Nombre&"]Datos!"&LEFT(SUBSTITUTE(ADDRESS(1,RIGHT(Formulas!AT8)+2),"$",""))&Formulas!AR8+1, IFERROR(INDEX(Datos!$A$2:$K$101,Formulas!AR8,RIGHT(Formulas!AT8)+2),"")))} | AS11: {=IF(OR(Formulas!AT9=0,Formulas!AT9=""),"",HYPERLINK("["&Archivo_Nombre&"]Datos!"&LEFT(SUBSTITUTE(ADDRESS(1,Formulas!AT9+2),"$",""))&Formulas!AS9+1, IFERROR(INDEX(Datos!$A$2:$K$101,Formulas!AS9,Formulas!AT9+2),"")))} | AV11: {=IF(OR(Formulas!AX8=0,Formulas!AX8="",RIGHT(Formulas!AY8)="0"),"", HYPERLINK("["&Archivo_Nombre&"]Datos!"&LEFT(SUBSTITUTE(ADDRESS(1,IF(Formulas!AX8=1,1,RIGHT(Formulas!AY8)+2)),"$",""))&Formulas!AW8+1, IFERROR(INDEX(Datos!$A$1:$K$1,1,RIGHT(Formulas!AY8)+2)&IF(Formulas!AX8=1," "&Formulas!AW8,"")&":","")))} | AW11: {=IF(OR(Formulas!AX8=0,Formulas!AX8="",RIGHT(Formulas!AY8)="0"),"", HYPERLINK("["&Archivo_Nombre&"]Datos!"&LEFT(SUBSTITUTE(ADDRESS(1,RIGHT(Formulas!AY8)+2),"$",""))&Formulas!AW8+1, IFERROR(INDEX(Datos!$A$2:$K$101,Formulas!AW8,RIGHT(Formulas!AY8)+2),"")))} | AX11: {=IF(OR(Formulas!AY9=0,Formulas!AY9=""),"",HYPERLINK("["&Archivo_Nombre&"]Datos!"&LEFT(SUBSTITUTE(ADDRESS(1,Formulas!AY9+2),"$",""))&Formulas!AX9+1, IFERROR(INDEX(Datos!$A$2:$K$101,Formulas!AX9,Formulas!AY9+2),"")))}
